ERROR:root:bot iniciado
ERROR:apscheduler.executors.default:Job "gerenciador (trigger: cron[day_of_week='0-6', hour='0', minute='0'], next run at: 2023-12-13 00:00:00 -03)" raised an exception
Traceback (most recent call last):
  File "/data/user/0/ru.iiec.pydroid3/files/arm-linux-androideabi/lib/python3.9/site-packages/pymysql/connections.py", line 756, in _write_bytes
    self._sock.sendall(data)
ConnectionAbortedError: [Errno 103] Software caused connection abort

During handling of the above exception, another exception occurred:

Traceback (most recent call last):
  File "/data/user/0/ru.iiec.pydroid3/files/arm-linux-androideabi/lib/python3.9/site-packages/apscheduler/executors/base.py", line 125, in run_job
    retval = job.func(*job.args, **job.kwargs)
  File "<string>", line 669, in gerenciador
  File "/storage/emulated/0/htdocs/suporte/userbot/utils.py", line 50, in postar_ps
    funcao_ps()
  File "/storage/emulated/0/htdocs/suporte/userbot/palavrasecreta.py", line 22, in postando_palavra_secreta
    tema = executa_query('SELECT tema FROM palavra_secreta WHERE postado = (SELECT MIN(postado) FROM palavra_secreta) ORDER BY RAND () LIMIT 1', 'select')[0]
  File "/storage/emulated/0/htdocs/suporte/userbot/database.py", line 15, in executa_query
    cursor.execute(query)
  File "/data/user/0/ru.iiec.pydroid3/files/arm-linux-androideabi/lib/python3.9/site-packages/pymysql/cursors.py", line 148, in execute
    result = self._query(query)
  File "/data/user/0/ru.iiec.pydroid3/files/arm-linux-androideabi/lib/python3.9/site-packages/pymysql/cursors.py", line 310, in _query
    conn.query(q)
  File "/data/user/0/ru.iiec.pydroid3/files/arm-linux-androideabi/lib/python3.9/site-packages/pymysql/connections.py", line 547, in query
    self._execute_command(COMMAND.COM_QUERY, sql)
  File "/data/user/0/ru.iiec.pydroid3/files/arm-linux-androideabi/lib/python3.9/site-packages/pymysql/connections.py", line 814, in _execute_command
    self._write_bytes(packet)
  File "/data/user/0/ru.iiec.pydroid3/files/arm-linux-androideabi/lib/python3.9/site-packages/pymysql/connections.py", line 759, in _write_bytes
    raise err.OperationalError(
pymysql.err.OperationalError: (2006, "MySQL server has gone away (ConnectionAbortedError(103, 'Software caused connection abort'))")
